Workbook

Sheet Scenario 1
B1: Scenario 1: | C1: Actual Daily Consumption of kW is less than 50% of Contract Demand
C4: Sample Calculation
C5: Heads | D5: Value | E5: Details
C6: Santioned | D6: 10 | E6: KVA
C7: Fixed charges | D7: 150 | E7: Rs/ kW on unit consumption with a condition if CD exceeds 50% of CD or MD whichever is higher per month, then all days caculation will be on max value
C8: Energy charges | D8: 4.3 | E8: Rs/ kWh on unit consumption
C9: FPPAS ( Fuel & Power Production Adjustment Surcharge) | D9: 0.66 | E9: DVC would provide by end of every month and this would be forward calculation for next month
C10: Rebate | D10: 0.03 | E10: % on Energy Charge
C11: ED ( Energy Duty) | D11: 0.06 | E11: %age flat on [(EC +FPPAS) ]
C12: Penalty | D12: 1.5 | E12: 110% of Contract Demand
C13: Month | D13: 45870
C14: No. of Days | D14: =DAY(EOMONTH(D13,0)) -> 31
C16: Variables | D16: kVA | E16: kW
C17: 50% of Contract Demand | D17: =50%*D6 -> 5 | E17: =D17*$E$24 -> 4.25
C18: Contract Demand | D18: 10 | E18: =D18*$E$24 -> 8.5
C19: 110% of Contract Demand | D19: =110%*D18 -> 11 | E19: =D19*$E$24 -> 9.35
D22: Sample Daily Consumption Data for June'25
D23: No. of Hrs | E23: 24 | K23: Daily charge Calculation
D24: Power Factor | E24: 0.85
L25: Fixed Charges in Rs | M25: Energy Charge in Rs | N25: FPPAS Charges | O25: Energy Duty | P25: Rebate | Q25: Penalty | R25: Opening Balance
B26: Daily Profile | E26: Daily Profile | G26: Instantenous Profile | I26: Contract Demand in kW | J26: Formula | L26: =kW x (Fixed Charge per kW/ No of calender days) | M26: =kwh x Energy Charges | N26: =kwh x FPPAS Charge | O26: =ED % x (Energy Charge+FPPAS Charge) | P26: =Rebate% x Energy Charge | Q26: =if (kw>=110% of Contract Demand , 1.5 x Energy Charges x (Maximum Demand - Contract Demand)
B27: July (kWh) Sample | D27: Date | E27: (kWh) Sample | G27: (kW) Sample | I27: Calculation (kW) | R27: 0
B28: 41.5 | D28: =D13 -> 45870 | E28: 45 | G28: 1.875 | I28: =IF(G28="", "", MIN($E$18, IF(MAX($G$28:$G$57)>$E$17, MAX($G$28:$G$57), G28))) -> 1.875 | K28: =D28 -> 45870 | L28: =ROUNDUP(I28*($D$7/$D$14),4) -> 9.0726 | M28: =ROUNDUP(E28*$D$8,4) -> 193.5 | N28: =B28*$D$9 -> 27.39 | O28: =ROUNDUP($D$11*(M28+N28),4) -> 13.2534 | P28: =ROUNDUP(-M28*$D$10,4) -> -5.805 | Q28: =IF(G28>=$E$19,1.5*$D$7*(G28-$E$18),0) -> 0 | R28: =ROUNDUP(R27-(L28+M28+N28+O28+P28+Q28),4) -> -237.411
B29: 51.5 | D29: =D28+1 -> 45871 | E29: 55 | G29: 2.2916667 | I29: =IF(G29="", "", MIN($E$18, IF(MAX($G$28:$G$58)>$E$17, MAX($G$28:$G$58), G29))) -> 2.2916667 | K29: =K28+1 -> 45871 | L29: =ROUNDUP(I29*($D$7/$D$14),4) -> 11.0888 | M29: =ROUNDUP(E29*$D$8,4) -> 236.5 | N29: =B29*$D$9 -> 33.99 | O29: =ROUNDUP($D$11*(M29+N29),4) -> 16.2294 | P29: =ROUNDUP(-M29*$D$10,4) -> -7.095 | Q29: =IF(G29>=$E$19,1.5*$D$7*(G29-$E$18),0) -> 0 | R29: =ROUNDUP(R28-(L29+M29+N29+O29+P29+Q29),4) -> -528.1242
B30: 68.5 | D30: =D29+1 -> 45872 | E30: 72 | G30: 3 | I30: =IF(G30="", "", MIN($E$18, IF(MAX($G$28:$G$58)>$E$17, MAX($G$28:$G$58), G30))) -> 3 | K30: =K29+1 -> 45872 | L30: =ROUNDUP(I30*($D$7/$D$14),4) -> 14.5162 | M30: =ROUNDUP(E30*$D$8,4) -> 309.6 | N30: =B30*$D$9 -> 45.21 | O30: =ROUNDUP($D$11*(M30+N30),4) -> 21.2886 | P30: =ROUNDUP(-M30*$D$10,4) -> -9.288 | Q30: =IF(G30>=$E$19,1.5*$D$7*(G30-$E$18),0) -> 0 | R30: =ROUNDUP(R29-(L30+M30+N30+O30+P30+Q30),4) -> -909.451
B31: 81.5 | D31: =D30+1 -> 45873 | E31: 85 | G31: 3.5416667 | I31: =IF(G31="", "", MIN($E$18, IF(MAX($G$28:$G$58)>$E$17, MAX($G$28:$G$58), G31))) -> 3.5416667 | K31: =K30+1 -> 45873 | L31: =ROUNDUP(I31*($D$7/$D$14),4) -> 17.1371 | M31: =ROUNDUP(E31*$D$8,4) -> 365.5 | N31: =B31*$D$9 -> 53.79 | O31: =ROUNDUP($D$11*(M31+N31),4) -> 25.1574 | P31: =ROUNDUP(-M31*$D$10,4) -> -10.965 | Q31: =IF(G31>=$E$19,1.5*$D$7*(G31-$E$18),0) -> 0 | R31: =ROUNDUP(R30-(L31+M31+N31+O31+P31+Q31),4) -> -1360.0705
B32: 61.5 | D32: =D31+1 -> 45874 | E32: 65 | G32: 2.7083333 | I32: =IF(G32="", "", MIN($E$18, IF(MAX($G$28:$G$58)>$E$17, MAX($G$28:$G$58), G32))) -> 2.7083333 | K32: =K31+1 -> 45874 | L32: =ROUNDUP(I32*($D$7/$D$14),4) -> 13.1049 | M32: =ROUNDUP(E32*$D$8,4) -> 279.5 | N32: =B32*$D$9 -> 40.59 | O32: =ROUNDUP($D$11*(M32+N32),4) -> 19.2054 | P32: =ROUNDUP(-M32*$D$10,4) -> -8.385 | Q32: =IF(G32>=$E$19,1.5*$D$7*(G32-$E$18),0) -> 0 | R32: =ROUNDUP(R31-(L32+M32+N32+O32+P32+Q32),4) -> -1704.0858
B33: 78.5 | D33: =D32+1 -> 45875 | E33: 82 | G33: 3.4166667 | I33: =IF(G33="", "", MIN($E$18, IF(MAX($G$28:$G$58)>$E$17, MAX($G$28:$G$58), G33))) -> 3.4166667 | K33: =K32+1 -> 45875 | L33: =ROUNDUP(I33*($D$7/$D$14),4) -> 16.5323 | M33: =ROUNDUP(E33*$D$8,4) -> 352.6 | N33: =B33*$D$9 -> 51.81 | O33: =ROUNDUP($D$11*(M33+N33),4) -> 24.2646 | P33: =ROUNDUP(-M33*$D$10,4) -> -10.578 | Q33: =IF(G33>=$E$19,1.5*$D$7*(G33-$E$18),0) -> 0 | R33: =ROUNDUP(R32-(L33+M33+N33+O33+P33+Q33),4) -> -2138.7147
B34: 71.5 | D34: =D33+1 -> 45876 | E34: 75 | G34: 3.125 | I34: =IF(G34="", "", MIN($E$18, IF(MAX($G$28:$G$58)>$E$17, MAX($G$28:$G$58), G34))) -> 3.125 | K34: =K33+1 -> 45876 | L34: =ROUNDUP(I34*($D$7/$D$14),4) -> 15.121 | M34: =ROUNDUP(E34*$D$8,4) -> 322.5 | N34: =B34*$D$9 -> 47.19 | O34: =ROUNDUP($D$11*(M34+N34),4) -> 22.1814 | P34: =ROUNDUP(-M34*$D$10,4) -> -9.675 | Q34: =IF(G34>=$E$19,1.5*$D$7*(G34-$E$18),0) -> 0 | R34: =ROUNDUP(R33-(L34+M34+N34+O34+P34+Q34),4) -> -2536.0321
B35: 91.5 | D35: =D34+1 -> 45877 | E35: 95 | G35: 3.9583333 | I35: =IF(G35="", "", MIN($E$18, IF(MAX($G$28:$G$58)>$E$17, MAX($G$28:$G$58), G35))) -> 3.9583333 | K35: =K34+1 -> 45877 | L35: =ROUNDUP(I35*($D$7/$D$14),4) -> 19.1533 | M35: =ROUNDUP(E35*$D$8,4) -> 408.5 | N35: =B35*$D$9 -> 60.39 | O35: =ROUNDUP($D$11*(M35+N35),4) -> 28.1334 | P35: =ROUNDUP(-M35*$D$10,4) -> -12.255 | Q35: =IF(G35>=$E$19,1.5*$D$7*(G35-$E$18),0) -> 0 | R35: =ROUNDUP(R34-(L35+M35+N35+O35+P35+Q35),4) -> -3039.9538
B36: 84.5 | D36: =D35+1 -> 45878 | E36: 88 | G36: 3.6666667 | I36: =IF(G36="", "", MIN($E$18, IF(MAX($G$28:$G$58)>$E$17, MAX($G$28:$G$58), G36))) -> 3.6666667 | K36: =K35+1 -> 45878 | L36: =ROUNDUP(I36*($D$7/$D$14),4) -> 17.742 | M36: =ROUNDUP(E36*$D$8,4) -> 378.4 | N36: =B36*$D$9 -> 55.77 | O36: =ROUNDUP($D$11*(M36+N36),4) -> 26.0502 | P36: =ROUNDUP(-M36*$D$10,4) -> -11.352 | Q36: =IF(G36>=$E$19,1.5*$D$7*(G36-$E$18),0) -> 0 | R36: =ROUNDUP(R35-(L36+M36+N36+O36+P36+Q36),4) -> -3506.564
B37: 93.5 | D37: =D36+1 -> 45879 | E37: 98 | G37: 4.0833333 | I37: =IF(G37="", "", MIN($E$18, IF(MAX($G$28:$G$58)>$E$17, MAX($G$28:$G$58), G37))) -> 4.0833333 | K37: =K36+1 -> 45879 | L37: =ROUNDUP(I37*($D$7/$D$14),4) -> 19.7581 | M37: =ROUNDUP(E37*$D$8,4) -> 421.4 | N37: =B37*$D$9 -> 61.71 | O37: =ROUNDUP($D$11*(M37+N37),4) -> 28.9866 | P37: =ROUNDUP(-M37*$D$10,4) -> -12.642 | Q37: =IF(G37>=$E$19,1.5*$D$7*(G37-$E$18),0) -> 0 | R37: =ROUNDUP(R36-(L37+M37+N37+O37+P37+Q37),4) -> -4025.7767
B38: 90.5 | D38: =D37+1 -> 45880 | E38: 95 | G38: 3.9583333 | I38: =IF(G38="", "", MIN($E$18, IF(MAX($G$28:$G$58)>$E$17, MAX($G$28:$G$58), G38))) -> 3.9583333 | K38: =K37+1 -> 45880 | L38: =ROUNDUP(I38*($D$7/$D$14),4) -> 19.1533 | M38: =ROUNDUP(E38*$D$8,4) -> 408.5 | N38: =B38*$D$9 -> 59.73 | O38: =ROUNDUP($D$11*(M38+N38),4) -> 28.0938 | P38: =ROUNDUP(-M38*$D$10,4) -> -12.255 | Q38: =IF(G38>=$E$19,1.5*$D$7*(G38-$E$18),0) -> 0 | R38: =ROUNDUP(R37-(L38+M38+N38+O38+P38+Q38),4) -> -4528.9988
B39: 70.5 | D39: =D38+1 -> 45881 | E39: 75 | G39: 3.125 | I39: =IF(G39="", "", MIN($E$18, IF(MAX($G$28:$G$58)>$E$17, MAX($G$28:$G$58), G39))) -> 3.125 | K39: =K38+1 -> 45881 | L39: =ROUNDUP(I39*($D$7/$D$14),4) -> 15.121 | M39: =ROUNDUP(E39*$D$8,4) -> 322.5 | N39: =B39*$D$9 -> 46.53 | O39: =ROUNDUP($D$11*(M39+N39),4) -> 22.1418 | P39: =ROUNDUP(-M39*$D$10,4) -> -9.675 | Q39: =IF(G39>=$E$19,1.5*$D$7*(G39-$E$18),0) -> 0 | R39: =ROUNDUP(R38-(L39+M39+N39+O39+P39+Q39),4) -> -4925.6166
B40: 60.5 | D40: =D39+1 -> 45882 | E40: 65 | G40: 2.7083333 | I40: =IF(G40="", "", MIN($E$18, IF(MAX($G$28:$G$58)>$E$17, MAX($G$28:$G$58), G40))) -> 2.7083333 | K40: =K39+1 -> 45882 | L40: =ROUNDUP(I40*($D$7/$D$14),4) -> 13.1049 | M40: =ROUNDUP(E40*$D$8,4) -> 279.5 | N40: =B40*$D$9 -> 39.93 | O40: =ROUNDUP($D$11*(M40+N40),4) -> 19.1658 | P40: =ROUNDUP(-M40*$D$10,4) -> -8.385 | Q40: =IF(G40>=$E$19,1.5*$D$7*(G40-$E$18),0) -> 0 | R40: =ROUNDUP(R39-(L40+M40+N40+O40+P40+Q40),4) -> -5268.9323
... B58: 92.5 | D58: =D57+1 -> 45900 | E58: 95 | G58: 3.9583333 | I58: =IF(G58="", "", MIN($E$18, IF(MAX($G$28:$G$58)>$E$17, MAX($G$28:$G$58), G58))) -> 3.9583333 | K58: =K57+1 -> 45900 | L58: =ROUNDUP(I58*($D$7/$D$14),4) -> 19.1533 | M58: =ROUNDUP(E58*$D$8,4) -> 408.5 | N58: =B58*$D$9 -> 61.05 | O58: =ROUNDUP($D$11*(M58+N58),4) -> 28.173 | P58: =ROUNDUP(-M58*$D$10,4) -> -12.255 | Q58: =IF(G58>=$E$19,1.5*$D$7*(G58-$E$18),0) -> 0 | R58: =ROUNDUP(R57-(L58+M58+N58+O58+P58+Q58),4) -> -13969.218
K61: Fixed Charges | M61: =SUM(L28:L59) -> 532.663
K62: Energy Charges | M62: =SUM(M28:M59) -> 11330.5
K63: FPPS | M63: =SUM(N28:N59) -> 1666.17
K64: ED | M64: =SUM(O28:O59) -> 779.8002
...

Sheet Scenario 2
A1: Scenario 2: | B1: Actual Daily Consumption of kW is more than 50% of Contract Demand but less than 110% contract Demand
B4: Sample Calculation
B5: Heads | C5: Value | D5: Details
B6: Santioned | C6: 10 | D6: KVA
B7: Fixed charges | C7: 150 | D7: Rs/ kW on unit consumption with a condition if CD exceeds 50% of CD or MD whichever is higher per month, then all days caculation will be on max value
B8: Energy charges | C8: 4.3 | D8: Rs/ kWh on unit consumption
B9: FPPAS ( Fuel & Power Production Adjustment Surcharge) | C9: 0.66 | D9: DVC would provide by end of every month and this would be forward calculation for next month
B10: Rebate | C10: 0.03 | D10: % on Energy Charge
B11: ED ( Energy Duty) | C11: 0.06 | D11: %age flat on [(EC +FPPAS) ]
B12: Penalty | C12: 1.5 | D12: 110% of Contract Demand
B13: Month | C13: 45870
B14: No. of Days | C14: =DAY(EOMONTH(C13,0)) -> 31
B16: Variables | C16: kVA | D16: kW
B17: 50% of Contract Demand | C17: =50%*C6 -> 5 | D17: =C17*$D$24 -> 4.25
B18: Contract Demand | C18: 10 | D18: =C18*$D$24 -> 8.5
B19: 110% of Contract Demand | C19: =110%*C18 -> 11 | D19: =C19*$D$24 -> 9.35
C22: Sample Daily Consumption Data for June'25
C23: No. of Hrs | D23: 24 | J23: Daily charge Calculation
C24: Power Factor | D24: 0.85
K25: Fixed Charges in Rs | L25: Energy Charge in Rs | M25: FPPAS Charges | N25: Energy Duty | O25: Rebate | P25: Penalty | Q25: Opening Balance
A26: Daily Profile | D26: Daily Profile | F26: Instantenous Profile | H26: Contract Demand in kW | I26: Formula | K26: =kW x (Fixed Charge per kW/ No of calender days) | L26: =kwh x Energy Charges | M26: =kwh x FPPAS Charge | N26: =ED % x (Energy Charge+FPPAS Charge) | O26: =Rebate% x Energy Charge | P26: =if (kw>=110% of Contract Demand , 1.5 x Energy Charges x (Maximum Demand - Contract Demand)
A27: July (kWh) Sample | C27: Date | D27: (kWh) Sample | F27: (kW) Sample | H27: Calculation (kW) | Q27: 0
A28: 41.5 | C28: =C13 -> 45870 | D28: 45 | F28: 1.875 | H28: =IF(F28="", "", MIN($D$18, IF(MAX($F$28:$F$57)>$D$17, MAX($F$28:$F$57), F28))) -> 8.45 | J28: =C28 -> 45870 | K28: =ROUNDUP(H28*($C$7/$C$14),4) -> 40.8871 | L28: =ROUNDUP(D28*$C$8,4) -> 193.5 | M28: =A28*$C$9 -> 27.39 | N28: =ROUNDUP($C$11*(L28+M28),4) -> 13.2534 | O28: =ROUNDUP(-L28*$C$10,4) -> -5.805 | P28: =IF(F28>=$D$19,1.5*$C$7*(F28-$D$18),0) -> 0 | Q28: =ROUNDUP(Q27-(K28+L28+M28+N28+O28+P28),4) -> -269.2255 | R28: =Q28-'Scenario 1'!R28 -> -31.8145
A29: 51.5 | C29: =C28+1 -> 45871 | D29: 55 | F29: 2.2916667 | H29: =IF(F29="", "", MIN($D$18, IF(MAX($F$28:$F$58)>$D$17, MAX($F$28:$F$58), F29))) -> 8.45 | J29: =J28+1 -> 45871 | K29: =ROUNDUP(H29*($C$7/$C$14),4) -> 40.8871 | L29: =ROUNDUP(D29*$C$8,4) -> 236.5 | M29: =A29*$C$9 -> 33.99 | N29: =ROUNDUP($C$11*(L29+M29),4) -> 16.2294 | O29: =ROUNDUP(-L29*$C$10,4) -> -7.095 | P29: =IF(F29>=$D$19,1.5*$C$7*(F29-$D$18),0) -> 0 | Q29: =ROUNDUP(Q28-(K29+L29+M29+N29+O29+P29),4) -> -589.737 | R29: =Q29-'Scenario 1'!R29 -> -61.6128
A30: 68.5 | C30: =C29+1 -> 45872 | D30: 72 | F30: 3 | H30: =IF(F30="", "", MIN($D$18, IF(MAX($F$28:$F$58)>$D$17, MAX($F$28:$F$58), F30))) -> 8.45 | J30: =J29+1 -> 45872 | K30: =ROUNDUP(H30*($C$7/$C$14),4) -> 40.8871 | L30: =ROUNDUP(D30*$C$8,4) -> 309.6 | M30: =A30*$C$9 -> 45.21 | N30: =ROUNDUP($C$11*(L30+M30),4) -> 21.2886 | O30: =ROUNDUP(-L30*$C$10,4) -> -9.288 | P30: =IF(F30>=$D$19,1.5*$C$7*(F30-$D$18),0) -> 0 | Q30: =ROUNDUP(Q29-(K30+L30+M30+N30+O30+P30),4) -> -997.4347 | R30: =Q30-'Scenario 1'!R30 -> -87.9837
A31: 81.5 | C31: =C30+1 -> 45873 | D31: 85 | F31: 3.5416667 | H31: =IF(F31="", "", MIN($D$18, IF(MAX($F$28:$F$58)>$D$17, MAX($F$28:$F$58), F31))) -> 8.45 | J31: =J30+1 -> 45873 | K31: =ROUNDUP(H31*($C$7/$C$14),4) -> 40.8871 | L31: =ROUNDUP(D31*$C$8,4) -> 365.5 | M31: =A31*$C$9 -> 53.79 | N31: =ROUNDUP($C$11*(L31+M31),4) -> 25.1574 | O31: =ROUNDUP(-L31*$C$10,4) -> -10.965 | P31: =IF(F31>=$D$19,1.5*$C$7*(F31-$D$18),0) -> 0 | Q31: =ROUNDUP(Q30-(K31+L31+M31+N31+O31+P31),4) -> -1471.8042 | R31: =Q31-'Scenario 1'!R31 -> -111.7337
A32: 61.5 | C32: =C31+1 -> 45874 | D32: 65 | F32: 2.7083333 | H32: =IF(F32="", "", MIN($D$18, IF(MAX($F$28:$F$58)>$D$17, MAX($F$28:$F$58), F32))) -> 8.45 | J32: =J31+1 -> 45874 | K32: =ROUNDUP(H32*($C$7/$C$14),4) -> 40.8871 | L32: =ROUNDUP(D32*$C$8,4) -> 279.5 | M32: =A32*$C$9 -> 40.59 | N32: =ROUNDUP($C$11*(L32+M32),4) -> 19.2054 | O32: =ROUNDUP(-L32*$C$10,4) -> -8.385 | P32: =IF(F32>=$D$19,1.5*$C$7*(F32-$D$18),0) -> 0 | Q32: =ROUNDUP(Q31-(K32+L32+M32+N32+O32+P32),4) -> -1843.6017 | R32: =Q32-'Scenario 1'!R32 -> -139.5159
A33: 78.5 | C33: =C32+1 -> 45875 | D33: 82 | F33: 8.25 | H33: =IF(F33="", "", MIN($D$18, IF(MAX($F$28:$F$58)>$D$17, MAX($F$28:$F$58), F33))) -> 8.45 | J33: =J32+1 -> 45875 | K33: =ROUNDUP(H33*($C$7/$C$14),4) -> 40.8871 | L33: =ROUNDUP(D33*$C$8,4) -> 352.6 | M33: =A33*$C$9 -> 51.81 | N33: =ROUNDUP($C$11*(L33+M33),4) -> 24.2646 | O33: =ROUNDUP(-L33*$C$10,4) -> -10.578 | P33: =IF(F33>=$D$19,1.5*$C$7*(F33-$D$18),0) -> 0 | Q33: =ROUNDUP(Q32-(K33+L33+M33+N33+O33+P33),4) -> -2302.5854
A34: 71.5 | C34: =C33+1 -> 45876 | D34: 75 | F34: 3.125 | H34: =IF(F34="", "", MIN($D$18, IF(MAX($F$28:$F$58)>$D$17, MAX($F$28:$F$58), F34))) -> 8.45 | J34: =J33+1 -> 45876 | K34: =ROUNDUP(H34*($C$7/$C$14),4) -> 40.8871 | L34: =ROUNDUP(D34*$C$8,4) -> 322.5 | M34: =A34*$C$9 -> 47.19 | N34: =ROUNDUP($C$11*(L34+M34),4) -> 22.1814 | O34: =ROUNDUP(-L34*$C$10,4) -> -9.675 | P34: =IF(F34>=$D$19,1.5*$C$7*(F34-$D$18),0) -> 0 | Q34: =ROUNDUP(Q33-(K34+L34+M34+N34+O34+P34),4) -> -2725.6689
A35: 91.5 | C35: =C34+1 -> 45877 | D35: 95 | F35: 3.9583333 | H35: =IF(F35="", "", MIN($D$18, IF(MAX($F$28:$F$58)>$D$17, MAX($F$28:$F$58), F35))) -> 8.45 | J35: =J34+1 -> 45877 | K35: =ROUNDUP(H35*($C$7/$C$14),4) -> 40.8871 | L35: =ROUNDUP(D35*$C$8,4) -> 408.5 | M35: =A35*$C$9 -> 60.39 | N35: =ROUNDUP($C$11*(L35+M35),4) -> 28.1334 | O35: =ROUNDUP(-L35*$C$10,4) -> -12.255 | P35: =IF(F35>=$D$19,1.5*$C$7*(F35-$D$18),0) -> 0 | Q35: =ROUNDUP(Q34-(K35+L35+M35+N35+O35+P35),4) -> -3251.3244
A36: 84.5 | C36: =C35+1 -> 45878 | D36: 88 | F36: =3.66666666666667*0+8.35 -> 8.35 | H36: =IF(F36="", "", MIN($D$18, IF(MAX($F$28:$F$58)>$D$17, MAX($F$28:$F$58), F36))) -> 8.45 | J36: =J35+1 -> 45878 | K36: =ROUNDUP(H36*($C$7/$C$14),4) -> 40.8871 | L36: =ROUNDUP(D36*$C$8,4) -> 378.4 | M36: =A36*$C$9 -> 55.77 | N36: =ROUNDUP($C$11*(L36+M36),4) -> 26.0502 | O36: =ROUNDUP(-L36*$C$10,4) -> -11.352 | P36: =IF(F36>=$D$19,1.5*$C$7*(F36-$D$18),0) -> 0 | Q36: =ROUNDUP(Q35-(K36+L36+M36+N36+O36+P36),4) -> -3741.0797
A37: 93.5 | C37: =C36+1 -> 45879 | D37: 98 | F37: 4.0833333 | H37: =IF(F37="", "", MIN($D$18, IF(MAX($F$28:$F$58)>$D$17, MAX($F$28:$F$58), F37))) -> 8.45 | J37: =J36+1 -> 45879 | K37: =ROUNDUP(H37*($C$7/$C$14),4) -> 40.8871 | L37: =ROUNDUP(D37*$C$8,4) -> 421.4 | M37: =A37*$C$9 -> 61.71 | N37: =ROUNDUP($C$11*(L37+M37),4) -> 28.9866 | O37: =ROUNDUP(-L37*$C$10,4) -> -12.642 | P37: =IF(F37>=$D$19,1.5*$C$7*(F37-$D$18),0) -> 0 | Q37: =ROUNDUP(Q36-(K37+L37+M37+N37+O37+P37),4) -> -4281.4214
A38: 90.5 | C38: =C37+1 -> 45880 | D38: 95 | F38: 3.9583333 | H38: =IF(F38="", "", MIN($D$18, IF(MAX($F$28:$F$58)>$D$17, MAX($F$28:$F$58), F38))) -> 8.45 | J38: =J37+1 -> 45880 | K38: =ROUNDUP(H38*($C$7/$C$14),4) -> 40.8871 | L38: =ROUNDUP(D38*$C$8,4) -> 408.5 | M38: =A38*$C$9 -> 59.73 | N38: =ROUNDUP($C$11*(L38+M38),4) -> 28.0938 | O38: =ROUNDUP(-L38*$C$10,4) -> -12.255 | P38: =IF(F38>=$D$19,1.5*$C$7*(F38-$D$18),0) -> 0 | Q38: =ROUNDUP(Q37-(K38+L38+M38+N38+O38+P38),4) -> -4806.3773
A39: 70.5 | C39: =C38+1 -> 45881 | D39: 75 | F39: 3.125 | H39: =IF(F39="", "", MIN($D$18, IF(MAX($F$28:$F$58)>$D$17, MAX($F$28:$F$58), F39))) -> 8.45 | J39: =J38+1 -> 45881 | K39: =ROUNDUP(H39*($C$7/$C$14),4) -> 40.8871 | L39: =ROUNDUP(D39*$C$8,4) -> 322.5 | M39: =A39*$C$9 -> 46.53 | N39: =ROUNDUP($C$11*(L39+M39),4) -> 22.1418 | O39: =ROUNDUP(-L39*$C$10,4) -> -9.675 | P39: =IF(F39>=$D$19,1.5*$C$7*(F39-$D$18),0) -> 0 | Q39: =ROUNDUP(Q38-(K39+L39+M39+N39+O39+P39),4) -> -5228.7612
A40: 60.5 | C40: =C39+1 -> 45882 | D40: 65 | F40: 2.7083333 | H40: =IF(F40="", "", MIN($D$18, IF(MAX($F$28:$F$58)>$D$17, MAX($F$28:$F$58), F40))) -> 8.45 | J40: =J39+1 -> 45882 | K40: =ROUNDUP(H40*($C$7/$C$14),4) -> 40.8871 | L40: =ROUNDUP(D40*$C$8,4) -> 279.5 | M40: =A40*$C$9 -> 39.93 | N40: =ROUNDUP($C$11*(L40+M40),4) -> 19.1658 | O40: =ROUNDUP(-L40*$C$10,4) -> -8.385 | P40: =IF(F40>=$D$19,1.5*$C$7*(F40-$D$18),0) -> 0 | Q40: =ROUNDUP(Q39-(K40+L40+M40+N40+O40+P40),4) -> -5599.8591
A41: 70.5 | C41: =C40+1 -> 45883 | D41: 75 | F41: 3.125 | H41: =IF(F41="", "", MIN($D$18, IF(MAX($F$28:$F$58)>$D$17, MAX($F$28:$F$58), F41))) -> 8.45 | J41: =J40+1 -> 45883 | K41: =ROUNDUP(H41*($C$7/$C$14),4) -> 40.8871 | L41: =ROUNDUP(D41*$C$8,4) -> 322.5 | M41: =A41*$C$9 -> 46.53 | N41: =ROUNDUP($C$11*(L41+M41),4) -> 22.1418 | O41: =ROUNDUP(-L41*$C$10,4) -> -9.675 | P41: =IF(F41>=$D$19,1.5*$C$7*(F41-$D$18),0) -> 0 | Q41: =ROUNDUP(Q40-(K41+L41+M41+N41+O41+P41),4) -> -6022.243
A42: 90.5 | C42: =C41+1 -> 45884 | D42: 95 | F42: 3.9583333 | H42: =IF(F42="", "", MIN($D$18, IF(MAX($F$28:$F$58)>$D$17, MAX($F$28:$F$58), F42))) -> 8.45 | J42: =J41+1 -> 45884 | K42: =ROUNDUP(H42*($C$7/$C$14),4) -> 40.8871 | L42: =ROUNDUP(D42*$C$8,4) -> 408.5 | M42: =A42*$C$9 -> 59.73 | N42: =ROUNDUP($C$11*(L42+M42),4) -> 28.0938 | O42: =ROUNDUP(-L42*$C$10,4) -> -12.255 | P42: =IF(F42>=$D$19,1.5*$C$7*(F42-$D$18),0) -> 0 | Q42: =ROUNDUP(Q41-(K42+L42+M42+N42+O42+P42),4) -> -6547.1989
A43: 80.5 | C43: =C42+1 -> 45885 | D43: 85 | F43: 3.5416667 | H43: =IF(F43="", "", MIN($D$18, IF(MAX($F$28:$F$58)>$D$17, MAX($F$28:$F$58), F43))) -> 8.45 | J43: =J42+1 -> 45885 | K43: =ROUNDUP(H43*($C$7/$C$14),4) -> 40.8871 | L43: =ROUNDUP(D43*$C$8,4) -> 365.5 | M43: =A43*$C$9 -> 53.13 | N43: =ROUNDUP($C$11*(L43+M43),4) -> 25.1178 | O43: =ROUNDUP(-L43*$C$10,4) -> -10.965 | P43: =IF(F43>=$D$19,1.5*$C$7*(F43-$D$18),0) -> 0 | Q43: =ROUNDUP(Q42-(K43+L43+M43+N43+O43+P43),4) -> -7020.8688
A44: 83.5 | C44: =C43+1 -> 45886 | D44: 88 | F44: 3.6666667 | H44: =IF(F44="", "", MIN($D$18, IF(MAX($F$28:$F$58)>$D$17, MAX($F$28:$F$58), F44))) -> 8.45 | J44: =J43+1 -> 45886 | K44: =ROUNDUP(H44*($C$7/$C$14),4) -> 40.8871 | L44: =ROUNDUP(D44*$C$8,4) -> 378.4 | M44: =A44*$C$9 -> 55.11 | N44: =ROUNDUP($C$11*(L44+M44),4) -> 26.0106 | O44: =ROUNDUP(-L44*$C$10,4) -> -11.352 | P44: =IF(F44>=$D$19,1.5*$C$7*(F44-$D$18),0) -> 0 | Q44: =ROUNDUP(Q43-(K44+L44+M44+N44+O44+P44),4) -> -7509.9245
A45: 93.5 | C45: =C44+1 -> 45887 | D45: 98 | F45: 4.0833333 | H45: =IF(F45="", "", MIN($D$18, IF(MAX($F$28:$F$58)>$D$17, MAX($F$28:$F$58), F45))) -> 8.45 | J45: =J44+1 -> 45887 | K45: =ROUNDUP(H45*($C$7/$C$14),4) -> 40.8871 | L45: =ROUNDUP(D45*$C$8,4) -> 421.4 | M45: =A45*$C$9 -> 61.71 | N45: =ROUNDUP($C$11*(L45+M45),4) -> 28.9866 | O45: =ROUNDUP(-L45*$C$10,4) -> -12.642 | P45: =IF(F45>=$D$19,1.5*$C$7*(F45-$D$18),0) -> 0 | Q45: =ROUNDUP(Q44-(K45+L45+M45+N45+O45+P45),4) -> -8050.2662
...

Sheet Scenario 3
A1: Scenario 3: | B1: Actual Daily Consumption of kW is more than 110% Contract Demand
B4: Sample Calculation
B5: Heads | C5: Value | D5: Details
B6: Santioned | C6: 10 | D6: KVA
B7: Fixed charges | C7: 150 | D7: Rs/ kW on unit consumption with a condition if CD exceeds 50% of CD or MD whichever is higher per month, then all days caculation will be on max value
B8: Energy charges | C8: 4.3 | D8: Rs/ kWh on unit consumption
B9: FPPAS ( Fuel & Power Production Adjustment Surcharge) | C9: 0.66 | D9: DVC would provide by end of every month and this would be forward calculation for next month
B10: Rebate | C10: 0.03 | D10: % on Energy Charge
B11: ED ( Energy Duty) | C11: 0.06 | D11: %age flat on [(EC +FPPAS) ]
B12: Penalty | C12: 1.5 | D12: 110% of Contract Demand
B13: Month | C13: 45870
B14: No. of Days | C14: =DAY(EOMONTH(C13,0)) -> 31
B16: Variables | C16: kVA | D16: kW
B17: 50% of Contract Demand | C17: =50%*C6 -> 5 | D17: =C17*$D$24 -> 4.25
B18: Contract Demand | C18: 10 | D18: =C18*$D$24 -> 8.5
B19: 110% of Contract Demand | C19: =110%*C18 -> 11 | D19: =C19*$D$24 -> 9.35
C22: Sample Daily Consumption Data for June'25
C23: No. of Hrs | D23: 24 | J23: Daily charge Calculation
C24: Power Factor | D24: 0.85
K25: Fixed Charges in Rs | L25: Energy Charge in Rs | M25: FPPAS Charges | N25: Energy Duty | O25: Rebate | P25: Penalty | Q25: Opening Balance
A26: Daily Profile | D26: Daily Profile | F26: Instantenous Profile | H26: Contract Demand in kW | I26: Formula | K26: =kW x (Fixed Charge per kW/ No of calender days) | L26: =kwh x Energy Charges | M26: =kwh x FPPAS Charge | N26: =ED % x (Energy Charge+FPPAS Charge) | O26: =Rebate% x Energy Charge | P26: =if (kw>=110% of Contract Demand , 1.5 x Energy Charges x (Maximum Demand - Contract Demand)
A27: July (kWh) Sample | C27: Date | D27: (kWh) Sample | F27: (kW) Sample | H27: Calculation (kW) | Q27: 0
A28: 41.5 | C28: =C13 -> 45870 | D28: 45 | F28: 1.875 | H28: =IF(F28="", "", MIN($D$18, IF(MAX($F$28:$F$57)>$D$17, MAX($F$28:$F$57), F28))) -> 8.5 | J28: =C28 -> 45870 | K28: =ROUNDUP(H28*($C$7/$C$14),4) -> 41.1291 | L28: =ROUNDUP(D28*$C$8,4) -> 193.5 | M28: =A28*$C$9 -> 27.39 | N28: =ROUNDUP($C$11*(L28+M28),4) -> 13.2534 | O28: =ROUNDUP(-L28*$C$10,4) -> -5.805 | P28: =IF(F28>=$D$19,1.5*$C$7*(F28-$D$18),0) -> 0 | Q28: =ROUNDUP(Q27-(K28+L28+M28+N28+O28+P28),4) -> -269.4675 | R28: =Q28-'Scenario 1'!R28 -> -32.0565
A29: 51.5 | C29: =C28+1 -> 45871 | D29: 55 | F29: 2.2916667 | H29: =IF(F29="", "", MIN($D$18, IF(MAX($F$28:$F$58)>$D$17, MAX($F$28:$F$58), F29))) -> 8.5 | J29: =J28+1 -> 45871 | K29: =ROUNDUP(H29*($C$7/$C$14),4) -> 41.1291 | L29: =ROUNDUP(D29*$C$8,4) -> 236.5 | M29: =A29*$C$9 -> 33.99 | N29: =ROUNDUP($C$11*(L29+M29),4) -> 16.2294 | O29: =ROUNDUP(-L29*$C$10,4) -> -7.095 | P29: =IF(F29>=$D$19,1.5*$C$7*(F29-$D$18),0) -> 0 | Q29: =ROUNDUP(Q28-(K29+L29+M29+N29+O29+P29),4) -> -590.221 | R29: =Q29-'Scenario 1'!R29 -> -62.0968
A30: 68.5 | C30: =C29+1 -> 45872 | D30: 72 | F30: 3 | H30: =IF(F30="", "", MIN($D$18, IF(MAX($F$28:$F$58)>$D$17, MAX($F$28:$F$58), F30))) -> 8.5 | J30: =J29+1 -> 45872 | K30: =ROUNDUP(H30*($C$7/$C$14),4) -> 41.1291 | L30: =ROUNDUP(D30*$C$8,4) -> 309.6 | M30: =A30*$C$9 -> 45.21 | N30: =ROUNDUP($C$11*(L30+M30),4) -> 21.2886 | O30: =ROUNDUP(-L30*$C$10,4) -> -9.288 | P30: =IF(F30>=$D$19,1.5*$C$7*(F30-$D$18),0) -> 0 | Q30: =ROUNDUP(Q29-(K30+L30+M30+N30+O30+P30),4) -> -998.1607 | R30: =Q30-'Scenario 1'!R30 -> -88.7097
A31: 81.5 | C31: =C30+1 -> 45873 | D31: 85 | F31: 3.5416667 | H31: =IF(F31="", "", MIN($D$18, IF(MAX($F$28:$F$58)>$D$17, MAX($F$28:$F$58), F31))) -> 8.5 | J31: =J30+1 -> 45873 | K31: =ROUNDUP(H31*($C$7/$C$14),4) -> 41.1291 | L31: =ROUNDUP(D31*$C$8,4) -> 365.5 | M31: =A31*$C$9 -> 53.79 | N31: =ROUNDUP($C$11*(L31+M31),4) -> 25.1574 | O31: =ROUNDUP(-L31*$C$10,4) -> -10.965 | P31: =IF(F31>=$D$19,1.5*$C$7*(F31-$D$18),0) -> 0 | Q31: =ROUNDUP(Q30-(K31+L31+M31+N31+O31+P31),4) -> -1472.7722 | R31: =Q31-'Scenario 1'!R31 -> -112.7017
A32: 61.5 | C32: =C31+1 -> 45874 | D32: 65 | F32: 2.7083333 | H32: =IF(F32="", "", MIN($D$18, IF(MAX($F$28:$F$58)>$D$17, MAX($F$28:$F$58), F32))) -> 8.5 | J32: =J31+1 -> 45874 | K32: =ROUNDUP(H32*($C$7/$C$14),4) -> 41.1291 | L32: =ROUNDUP(D32*$C$8,4) -> 279.5 | M32: =A32*$C$9 -> 40.59 | N32: =ROUNDUP($C$11*(L32+M32),4) -> 19.2054 | O32: =ROUNDUP(-L32*$C$10,4) -> -8.385 | P32: =IF(F32>=$D$19,1.5*$C$7*(F32-$D$18),0) -> 0 | Q32: =ROUNDUP(Q31-(K32+L32+M32+N32+O32+P32),4) -> -1844.8117 | R32: =Q32-'Scenario 1'!R32 -> -140.7259
A33: 78.5 | C33: =C32+1 -> 45875 | D33: 82 | F33: 11.67 | H33: =IF(F33="", "", MIN($D$18, IF(MAX($F$28:$F$58)>$D$17, MAX($F$28:$F$58), F33))) -> 8.5 | J33: =J32+1 -> 45875 | K33: =ROUNDUP(H33*($C$7/$C$14),4) -> 41.1291 | L33: =ROUNDUP(D33*$C$8,4) -> 352.6 | M33: =A33*$C$9 -> 51.81 | N33: =ROUNDUP($C$11*(L33+M33),4) -> 24.2646 | O33: =ROUNDUP(-L33*$C$10,4) -> -10.578 | P33: =IF(F33>=$D$19,1.5*$C$7*(F33-$D$18),0) -> 713.25 | Q33: =ROUNDUP(Q32-(K33+L33+M33+N33+O33+P33),4) -> -3017.2874
A34: 71.5 | C34: =C33+1 -> 45876 | D34: 75 | F34: 3.125 | H34: =IF(F34="", "", MIN($D$18, IF(MAX($F$28:$F$58)>$D$17, MAX($F$28:$F$58), F34))) -> 8.5 | J34: =J33+1 -> 45876 | K34: =ROUNDUP(H34*($C$7/$C$14),4) -> 41.1291 | L34: =ROUNDUP(D34*$C$8,4) -> 322.5 | M34: =A34*$C$9 -> 47.19 | N34: =ROUNDUP($C$11*(L34+M34),4) -> 22.1814 | O34: =ROUNDUP(-L34*$C$10,4) -> -9.675 | P34: =IF(F34>=$D$19,1.5*$C$7*(F34-$D$18),0) -> 0 | Q34: =ROUNDUP(Q33-(K34+L34+M34+N34+O34+P34),4) -> -3440.6129
A35: 91.5 | C35: =C34+1 -> 45877 | D35: 95 | F35: 3.9583333 | H35: =IF(F35="", "", MIN($D$18, IF(MAX($F$28:$F$58)>$D$17, MAX($F$28:$F$58), F35))) -> 8.5 | J35: =J34+1 -> 45877 | K35: =ROUNDUP(H35*($C$7/$C$14),4) -> 41.1291 | L35: =ROUNDUP(D35*$C$8,4) -> 408.5 | M35: =A35*$C$9 -> 60.39 | N35: =ROUNDUP($C$11*(L35+M35),4) -> 28.1334 | O35: =ROUNDUP(-L35*$C$10,4) -> -12.255 | P35: =IF(F35>=$D$19,1.5*$C$7*(F35-$D$18),0) -> 0 | Q35: =ROUNDUP(Q34-(K35+L35+M35+N35+O35+P35),4) -> -3966.5104
A36: 84.5 | C36: =C35+1 -> 45878 | D36: 88 | F36: 3.6666667 | H36: =IF(F36="", "", MIN($D$18, IF(MAX($F$28:$F$58)>$D$17, MAX($F$28:$F$58), F36))) -> 8.5 | J36: =J35+1 -> 45878 | K36: =ROUNDUP(H36*($C$7/$C$14),4) -> 41.1291 | L36: =ROUNDUP(D36*$C$8,4) -> 378.4 | M36: =A36*$C$9 -> 55.77 | N36: =ROUNDUP($C$11*(L36+M36),4) -> 26.0502 | O36: =ROUNDUP(-L36*$C$10,4) -> -11.352 | P36: =IF(F36>=$D$19,1.5*$C$7*(F36-$D$18),0) -> 0 | Q36: =ROUNDUP(Q35-(K36+L36+M36+N36+O36+P36),4) -> -4456.5077
A37: 93.5 | C37: =C36+1 -> 45879 | D37: 98 | F37: 4.0833333 | H37: =IF(F37="", "", MIN($D$18, IF(MAX($F$28:$F$58)>$D$17, MAX($F$28:$F$58), F37))) -> 8.5 | J37: =J36+1 -> 45879 | K37: =ROUNDUP(H37*($C$7/$C$14),4) -> 41.1291 | L37: =ROUNDUP(D37*$C$8,4) -> 421.4 | M37: =A37*$C$9 -> 61.71 | N37: =ROUNDUP($C$11*(L37+M37),4) -> 28.9866 | O37: =ROUNDUP(-L37*$C$10,4) -> -12.642 | P37: =IF(F37>=$D$19,1.5*$C$7*(F37-$D$18),0) -> 0 | Q37: =ROUNDUP(Q36-(K37+L37+M37+N37+O37+P37),4) -> -4997.0914
A38: 90.5 | C38: =C37+1 -> 45880 | D38: 95 | F38: 3.9583333 | H38: =IF(F38="", "", MIN($D$18, IF(MAX($F$28:$F$58)>$D$17, MAX($F$28:$F$58), F38))) -> 8.5 | J38: =J37+1 -> 45880 | K38: =ROUNDUP(H38*($C$7/$C$14),4) -> 41.1291 | L38: =ROUNDUP(D38*$C$8,4) -> 408.5 | M38: =A38*$C$9 -> 59.73 | N38: =ROUNDUP($C$11*(L38+M38),4) -> 28.0938 | O38: =ROUNDUP(-L38*$C$10,4) -> -12.255 | P38: =IF(F38>=$D$19,1.5*$C$7*(F38-$D$18),0) -> 0 | Q38: =ROUNDUP(Q37-(K38+L38+M38+N38+O38+P38),4) -> -5522.2893
A39: 70.5 | C39: =C38+1 -> 45881 | D39: 75 | F39: 3.125 | H39: =IF(F39="", "", MIN($D$18, IF(MAX($F$28:$F$58)>$D$17, MAX($F$28:$F$58), F39))) -> 8.5 | J39: =J38+1 -> 45881 | K39: =ROUNDUP(H39*($C$7/$C$14),4) -> 41.1291 | L39: =ROUNDUP(D39*$C$8,4) -> 322.5 | M39: =A39*$C$9 -> 46.53 | N39: =ROUNDUP($C$11*(L39+M39),4) -> 22.1418 | O39: =ROUNDUP(-L39*$C$10,4) -> -9.675 | P39: =IF(F39>=$D$19,1.5*$C$7*(F39-$D$18),0) -> 0 | Q39: =ROUNDUP(Q38-(K39+L39+M39+N39+O39+P39),4) -> -5944.9152
A40: 60.5 | C40: =C39+1 -> 45882 | D40: 65 | F40: 2.7083333 | H40: =IF(F40="", "", MIN($D$18, IF(MAX($F$28:$F$58)>$D$17, MAX($F$28:$F$58), F40))) -> 8.5 | J40: =J39+1 -> 45882 | K40: =ROUNDUP(H40*($C$7/$C$14),4) -> 41.1291 | L40: =ROUNDUP(D40*$C$8,4) -> 279.5 | M40: =A40*$C$9 -> 39.93 | N40: =ROUNDUP($C$11*(L40+M40),4) -> 19.1658 | O40: =ROUNDUP(-L40*$C$10,4) -> -8.385 | P40: =IF(F40>=$D$19,1.5*$C$7*(F40-$D$18),0) -> 0 | Q40: =ROUNDUP(Q39-(K40+L40+M40+N40+O40+P40),4) -> -6316.2551
A41: 70.5 | C41: =C40+1 -> 45883 | D41: 75 | F41: =3.125*0+12.856 -> 12.856 | H41: =IF(F41="", "", MIN($D$18, IF(MAX($F$28:$F$58)>$D$17, MAX($F$28:$F$58), F41))) -> 8.5 | J41: =J40+1 -> 45883 | K41: =ROUNDUP(H41*($C$7/$C$14),4) -> 41.1291 | L41: =ROUNDUP(D41*$C$8,4) -> 322.5 | M41: =A41*$C$9 -> 46.53 | N41: =ROUNDUP($C$11*(L41+M41),4) -> 22.1418 | O41: =ROUNDUP(-L41*$C$10,4) -> -9.675 | P41: =IF(F41>=$D$19,1.5*$C$7*(F41-$D$18),0) -> 980.1 | Q41: =ROUNDUP(Q40-(K41+L41+M41+N41+O41+P41),4) -> -7718.981
A42: 90.5 | C42: =C41+1 -> 45884 | D42: 95 | F42: 3.9583333 | H42: =IF(F42="", "", MIN($D$18, IF(MAX($F$28:$F$58)>$D$17, MAX($F$28:$F$58), F42))) -> 8.5 | J42: =J41+1 -> 45884 | K42: =ROUNDUP(H42*($C$7/$C$14),4) -> 41.1291 | L42: =ROUNDUP(D42*$C$8,4) -> 408.5 | M42: =A42*$C$9 -> 59.73 | N42: =ROUNDUP($C$11*(L42+M42),4) -> 28.0938 | O42: =ROUNDUP(-L42*$C$10,4) -> -12.255 | P42: =IF(F42>=$D$19,1.5*$C$7*(F42-$D$18),0) -> 0 | Q42: =ROUNDUP(Q41-(K42+L42+M42+N42+O42+P42),4) -> -8244.1789
A43: 80.5 | C43: =C42+1 -> 45885 | D43: 85 | F43: 3.5416667 | H43: =IF(F43="", "", MIN($D$18, IF(MAX($F$28:$F$58)>$D$17, MAX($F$28:$F$58), F43))) -> 8.5 | J43: =J42+1 -> 45885 | K43: =ROUNDUP(H43*($C$7/$C$14),4) -> 41.1291 | L43: =ROUNDUP(D43*$C$8,4) -> 365.5 | M43: =A43*$C$9 -> 53.13 | N43: =ROUNDUP($C$11*(L43+M43),4) -> 25.1178 | O43: =ROUNDUP(-L43*$C$10,4) -> -10.965 | P43: =IF(F43>=$D$19,1.5*$C$7*(F43-$D$18),0) -> 0 | Q43: =ROUNDUP(Q42-(K43+L43+M43+N43+O43+P43),4) -> -8718.0908
A44: 83.5 | C44: =C43+1 -> 45886 | D44: 88 | F44: 3.6666667 | H44: =IF(F44="", "", MIN($D$18, IF(MAX($F$28:$F$58)>$D$17, MAX($F$28:$F$58), F44))) -> 8.5 | J44: =J43+1 -> 45886 | K44: =ROUNDUP(H44*($C$7/$C$14),4) -> 41.1291 | L44: =ROUNDUP(D44*$C$8,4) -> 378.4 | M44: =A44*$C$9 -> 55.11 | N44: =ROUNDUP($C$11*(L44+M44),4) -> 26.0106 | O44: =ROUNDUP(-L44*$C$10,4) -> -11.352 | P44: =IF(F44>=$D$19,1.5*$C$7*(F44-$D$18),0) -> 0 | Q44: =ROUNDUP(Q43-(K44+L44+M44+N44+O44+P44),4) -> -9207.3885
A45: 93.5 | C45: =C44+1 -> 45887 | D45: 98 | F45: 4.0833333 | H45: =IF(F45="", "", MIN($D$18, IF(MAX($F$28:$F$58)>$D$17, MAX($F$28:$F$58), F45))) -> 8.5 | J45: =J44+1 -> 45887 | K45: =ROUNDUP(H45*($C$7/$C$14),4) -> 41.1291 | L45: =ROUNDUP(D45*$C$8,4) -> 421.4 | M45: =A45*$C$9 -> 61.71 | N45: =ROUNDUP($C$11*(L45+M45),4) -> 28.9866 | O45: =ROUNDUP(-L45*$C$10,4) -> -12.642 | P45: =IF(F45>=$D$19,1.5*$C$7*(F45-$D$18),0) -> 0 | Q45: =ROUNDUP(Q44-(K45+L45+M45+N45+O45+P45),4) -> -9747.9722
...
