Workbook

Sheet WB_LT Comm_Sample
D2: Sample Calculation
D3: Heads | E3: Value | F3: Details
D4: Santioned | E4: 10 | F4: KVA
D5: Fixed charges | E5: 30 | F5: Rs/ kVA on unit consumption
D6: Energy charges (TOU)
B7: TOU1 | C7: Normal Time | D7: 06:00 Hrs to 17:00 Hrs | E7: 6.66 | F7: Rs/ kWh on unit consumption
B8: TOU2 | C8: Peak Time | D8: 17:00 Hrs to 23:00 Hrs | E8: 7.34 | F8: Rs/ kWh on unit consumption
B9: TOU3 | C9: Off-Peak Time | D9: 23:00 Hrs to 06:00 Hrs | E9: 5.59 | F9: Rs/ kWh on unit consumption
D10: Differential ECR ( Energy Charge Rate) | E10: 0.485 | F10: DVC would provide by end of every month and this would be forward calculation
D11: MVCA ( Monthly Variable Cost Adjustment) | E11: 0.05 | F11: DVC would provide by end of every month and this would be forward calculation
D12: Rebate | E12: 5 | F12: Rs on E-Bill for a month
D13: Month | E13: 45870
D14: No. of Days | E14: =DAY(EOMONTH(E13,0)) -> 31
D15: No, of hours | E15: =E14*24 -> 744
D16: Load Shedding Hours | E16: 3
D17: Remaining Hours | E17: =E15-E16 -> 741
D21: Variables | E21: KVA
D22: 85% of Contract Demand | E22: =85%*E4 -> 8.5
D23: Contract Demand | E23: =E4 -> 10
K27: =SUBTOTAL(9,K32:K62) -> 229.25806 | L27: =SUBTOTAL(9,L32:L62) -> 1998 | M27: =SUBTOTAL(9,M32:M62) -> 2936 | N27: =SUBTOTAL(9,N32:N62) -> 2795 | O27: =SUBTOTAL(9,O32:O62) -> 48.5026 | P27: =SUBTOTAL(9,P32:P62) -> 5.0003 | Q27: =SUBTOTAL(9,Q32:Q62) -> 0 | R27: =SUBTOTAL(9,R32:R62) -> 5
J28: Assumption : Rounded-up to 4 decimal points for calculation purpose
C29: 100 | K29: Fixed Charges in Rs | L29: Energy Charge in Rs | M29: Energy Charge in Rs | N29: Energy Charge in Rs | O29: Differential ECR in Rs | P29: MVCA in Rs | Q29: Rebate ( Voucher) in Rs | R29: Ebill Opted in Rs | S29: Opening Balance
C30: 2 Months Prior Daily profile | G30: Instantenous in KVA | K30: =Fixed Charge/ No. of Calender Days | L30: =kwh x Energy Charge | M30: =kwh x Energy Charge | N30: =kwh x Energy Charge | O30: =kwh (two month back) x Diff ECR Charge | P30: =kwh (Two month Back) x MVCA Charge | Q30: Pre Paid Voucher Online get 1% benefit | R30: =Rs 5 /No of Calender Days
C31: (kWh) | F31: Date | G31: (kVA) | H31: Voucher | L31: TOU1 Normal Time | M31: TOU2 Peak Time | N31: TOU3 Off-Peak Time | S31: 0
C32: =$C$29/$E$14 -> 3.2258065 | F32: =E13 -> 45870 | G32: 7 | J32: =F32 -> 45870 | K32: =ROUND((($E$5*$E$17*G32)/$E$15),0)/$E$14 -> 6.7419355 | L32: =('ED Cal_Sample'!$J$11/'WB_LT Comm_Sample'!$E$14)*$E$7 -> 64.451613 | M32: =('ED Cal_Sample'!$K$11/'WB_LT Comm_Sample'!$E$14)*$E$8 -> 94.709677 | N32: =('ED Cal_Sample'!$L$11/'WB_LT Comm_Sample'!$E$14)*$E$9 -> 90.16129 | O32: =ROUNDUP(C32*$E$10,4) -> 1.5646 | P32: =ROUNDUP(C32*$E$11,4) -> 0.1613 | Q32: =H32*(100%+1%) -> 0 | R32: =$E$12/$E$14 -> 0.16129032 | S32: =ROUNDUP((S31-(K32+L32+M32+N32+O32+P32)),4)+Q32+R32 -> -257.62921
C33: =$C$29/$E$14 -> 3.2258065 | F33: =F32+1 -> 45871 | G33: 7 | J33: =J32+1 -> 45871 | K33: =ROUND((($E$5*$E$17*G33)/$E$15),0)/$E$14 -> 6.7419355 | L33: =('ED Cal_Sample'!$J$11/'WB_LT Comm_Sample'!$E$14)*$E$7 -> 64.451613 | M33: =('ED Cal_Sample'!$K$11/'WB_LT Comm_Sample'!$E$14)*$E$8 -> 94.709677 | N33: =('ED Cal_Sample'!$L$11/'WB_LT Comm_Sample'!$E$14)*$E$9 -> 90.16129 | O33: =ROUNDUP(C33*$E$10,4) -> 1.5646 | P33: =ROUNDUP(C33*$E$11,4) -> 0.1613 | Q33: =H33*(100%+1%) -> 0 | R33: =$E$12/$E$14 -> 0.16129032 | S33: =ROUNDUP((S32-(K33+L33+M33+N33+O33+P33)),4)+Q33+R33 -> -515.25841
C34: =$C$29/$E$14 -> 3.2258065 | F34: =F33+1 -> 45872 | G34: 7 | J34: =J33+1 -> 45872 | K34: =ROUND((($E$5*$E$17*G34)/$E$15),0)/$E$14 -> 6.7419355 | L34: =('ED Cal_Sample'!$J$11/'WB_LT Comm_Sample'!$E$14)*$E$7 -> 64.451613 | M34: =('ED Cal_Sample'!$K$11/'WB_LT Comm_Sample'!$E$14)*$E$8 -> 94.709677 | N34: =('ED Cal_Sample'!$L$11/'WB_LT Comm_Sample'!$E$14)*$E$9 -> 90.16129 | O34: =ROUNDUP(C34*$E$10,4) -> 1.5646 | P34: =ROUNDUP(C34*$E$11,4) -> 0.1613 | Q34: =H34*(100%+1%) -> 0 | R34: =$E$12/$E$14 -> 0.16129032 | S34: =ROUNDUP((S33-(K34+L34+M34+N34+O34+P34)),4)+Q34+R34 -> -772.88761
C35: =$C$29/$E$14 -> 3.2258065 | F35: =F34+1 -> 45873 | G35: 7 | J35: =J34+1 -> 45873 | K35: =ROUND((($E$5*$E$17*G35)/$E$15),0)/$E$14 -> 6.7419355 | L35: =('ED Cal_Sample'!$J$11/'WB_LT Comm_Sample'!$E$14)*$E$7 -> 64.451613 | M35: =('ED Cal_Sample'!$K$11/'WB_LT Comm_Sample'!$E$14)*$E$8 -> 94.709677 | N35: =('ED Cal_Sample'!$L$11/'WB_LT Comm_Sample'!$E$14)*$E$9 -> 90.16129 | O35: =ROUNDUP(C35*$E$10,4) -> 1.5646 | P35: =ROUNDUP(C35*$E$11,4) -> 0.1613 | Q35: =H35*(100%+1%) -> 0 | R35: =$E$12/$E$14 -> 0.16129032 | S35: =ROUNDUP((S34-(K35+L35+M35+N35+O35+P35)),4)+Q35+R35 -> -1030.5168
C36: =$C$29/$E$14 -> 3.2258065 | F36: =F35+1 -> 45874 | G36: 7 | J36: =J35+1 -> 45874 | K36: =ROUND((($E$5*$E$17*G36)/$E$15),0)/$E$14 -> 6.7419355 | L36: =('ED Cal_Sample'!$J$11/'WB_LT Comm_Sample'!$E$14)*$E$7 -> 64.451613 | M36: =('ED Cal_Sample'!$K$11/'WB_LT Comm_Sample'!$E$14)*$E$8 -> 94.709677 | N36: =('ED Cal_Sample'!$L$11/'WB_LT Comm_Sample'!$E$14)*$E$9 -> 90.16129 | O36: =ROUNDUP(C36*$E$10,4) -> 1.5646 | P36: =ROUNDUP(C36*$E$11,4) -> 0.1613 | Q36: =H36*(100%+1%) -> 0 | R36: =$E$12/$E$14 -> 0.16129032 | S36: =ROUNDUP((S35-(K36+L36+M36+N36+O36+P36)),4)+Q36+R36 -> -1288.146
C37: =$C$29/$E$14 -> 3.2258065 | F37: =F36+1 -> 45875 | G37: 7 | J37: =J36+1 -> 45875 | K37: =ROUND((($E$5*$E$17*G37)/$E$15),0)/$E$14 -> 6.7419355 | L37: =('ED Cal_Sample'!$J$11/'WB_LT Comm_Sample'!$E$14)*$E$7 -> 64.451613 | M37: =('ED Cal_Sample'!$K$11/'WB_LT Comm_Sample'!$E$14)*$E$8 -> 94.709677 | N37: =('ED Cal_Sample'!$L$11/'WB_LT Comm_Sample'!$E$14)*$E$9 -> 90.16129 | O37: =ROUNDUP(C37*$E$10,4) -> 1.5646 | P37: =ROUNDUP(C37*$E$11,4) -> 0.1613 | Q37: =H37*(100%+1%) -> 0 | R37: =$E$12/$E$14 -> 0.16129032 | S37: =ROUNDUP((S36-(K37+L37+M37+N37+O37+P37)),4)+Q37+R37 -> -1545.7752
C38: =$C$29/$E$14 -> 3.2258065 | F38: =F37+1 -> 45876 | G38: 7 | J38: =J37+1 -> 45876 | K38: =ROUND((($E$5*$E$17*G38)/$E$15),0)/$E$14 -> 6.7419355 | L38: =('ED Cal_Sample'!$J$11/'WB_LT Comm_Sample'!$E$14)*$E$7 -> 64.451613 | M38: =('ED Cal_Sample'!$K$11/'WB_LT Comm_Sample'!$E$14)*$E$8 -> 94.709677 | N38: =('ED Cal_Sample'!$L$11/'WB_LT Comm_Sample'!$E$14)*$E$9 -> 90.16129 | O38: =ROUNDUP(C38*$E$10,4) -> 1.5646 | P38: =ROUNDUP(C38*$E$11,4) -> 0.1613 | Q38: =H38*(100%+1%) -> 0 | R38: =$E$12/$E$14 -> 0.16129032 | S38: =ROUNDUP((S37-(K38+L38+M38+N38+O38+P38)),4)+Q38+R38 -> -1803.4044
C39: =$C$29/$E$14 -> 3.2258065 | F39: =F38+1 -> 45877 | G39: 7 | J39: =J38+1 -> 45877 | K39: =ROUND((($E$5*$E$17*G39)/$E$15),0)/$E$14 -> 6.7419355 | L39: =('ED Cal_Sample'!$J$11/'WB_LT Comm_Sample'!$E$14)*$E$7 -> 64.451613 | M39: =('ED Cal_Sample'!$K$11/'WB_LT Comm_Sample'!$E$14)*$E$8 -> 94.709677 | N39: =('ED Cal_Sample'!$L$11/'WB_LT Comm_Sample'!$E$14)*$E$9 -> 90.16129 | O39: =ROUNDUP(C39*$E$10,4) -> 1.5646 | P39: =ROUNDUP(C39*$E$11,4) -> 0.1613 | Q39: =H39*(100%+1%) -> 0 | R39: =$E$12/$E$14 -> 0.16129032 | S39: =ROUNDUP((S38-(K39+L39+M39+N39+O39+P39)),4)+Q39+R39 -> -2061.0336
C40: =$C$29/$E$14 -> 3.2258065 | F40: =F39+1 -> 45878 | G40: 7 | J40: =J39+1 -> 45878 | K40: =ROUND((($E$5*$E$17*G40)/$E$15),0)/$E$14 -> 6.7419355 | L40: =('ED Cal_Sample'!$J$11/'WB_LT Comm_Sample'!$E$14)*$E$7 -> 64.451613 | M40: =('ED Cal_Sample'!$K$11/'WB_LT Comm_Sample'!$E$14)*$E$8 -> 94.709677 | N40: =('ED Cal_Sample'!$L$11/'WB_LT Comm_Sample'!$E$14)*$E$9 -> 90.16129 | O40: =ROUNDUP(C40*$E$10,4) -> 1.5646 | P40: =ROUNDUP(C40*$E$11,4) -> 0.1613 | Q40: =H40*(100%+1%) -> 0 | R40: =$E$12/$E$14 -> 0.16129032 | S40: =ROUNDUP((S39-(K40+L40+M40+N40+O40+P40)),4)+Q40+R40 -> -2318.6628
C41: =$C$29/$E$14 -> 3.2258065 | F41: =F40+1 -> 45879 | G41: 7 | J41: =J40+1 -> 45879 | K41: =ROUND((($E$5*$E$17*G41)/$E$15),0)/$E$14 -> 6.7419355 | L41: =('ED Cal_Sample'!$J$11/'WB_LT Comm_Sample'!$E$14)*$E$7 -> 64.451613 | M41: =('ED Cal_Sample'!$K$11/'WB_LT Comm_Sample'!$E$14)*$E$8 -> 94.709677 | N41: =('ED Cal_Sample'!$L$11/'WB_LT Comm_Sample'!$E$14)*$E$9 -> 90.16129 | O41: =ROUNDUP(C41*$E$10,4) -> 1.5646 | P41: =ROUNDUP(C41*$E$11,4) -> 0.1613 | Q41: =H41*(100%+1%) -> 0 | R41: =$E$12/$E$14 -> 0.16129032 | S41: =ROUNDUP((S40-(K41+L41+M41+N41+O41+P41)),4)+Q41+R41 -> -2576.292
C42: =$C$29/$E$14 -> 3.2258065 | F42: =F41+1 -> 45880 | G42: 7 | J42: =J41+1 -> 45880 | K42: =ROUND((($E$5*$E$17*G42)/$E$15),0)/$E$14 -> 6.7419355 | L42: =('ED Cal_Sample'!$J$11/'WB_LT Comm_Sample'!$E$14)*$E$7 -> 64.451613 | M42: =('ED Cal_Sample'!$K$11/'WB_LT Comm_Sample'!$E$14)*$E$8 -> 94.709677 | N42: =('ED Cal_Sample'!$L$11/'WB_LT Comm_Sample'!$E$14)*$E$9 -> 90.16129 | O42: =ROUNDUP(C42*$E$10,4) -> 1.5646 | P42: =ROUNDUP(C42*$E$11,4) -> 0.1613 | Q42: =H42*(100%+1%) -> 0 | R42: =$E$12/$E$14 -> 0.16129032 | S42: =ROUNDUP((S41-(K42+L42+M42+N42+O42+P42)),4)+Q42+R42 -> -2833.9212
C43: =$C$29/$E$14 -> 3.2258065 | F43: =F42+1 -> 45881 | G43: 7 | J43: =J42+1 -> 45881 | K43: =ROUND((($E$5*$E$17*G43)/$E$15),0)/$E$14 -> 6.7419355 | L43: =('ED Cal_Sample'!$J$11/'WB_LT Comm_Sample'!$E$14)*$E$7 -> 64.451613 | M43: =('ED Cal_Sample'!$K$11/'WB_LT Comm_Sample'!$E$14)*$E$8 -> 94.709677 | N43: =('ED Cal_Sample'!$L$11/'WB_LT Comm_Sample'!$E$14)*$E$9 -> 90.16129 | O43: =ROUNDUP(C43*$E$10,4) -> 1.5646 | P43: =ROUNDUP(C43*$E$11,4) -> 0.1613 | Q43: =H43*(100%+1%) -> 0 | R43: =$E$12/$E$14 -> 0.16129032 | S43: =ROUNDUP((S42-(K43+L43+M43+N43+O43+P43)),4)+Q43+R43 -> -3091.5504
C44: =$C$29/$E$14 -> 3.2258065 | F44: =F43+1 -> 45882 | G44: =MAX('Addl MD Cal-Sample'!I22:I52) -> 28 | J44: =J43+1 -> 45882 | K44: =ROUND((($E$5*$E$17*G44)/$E$15),0)/$E$14 -> 27 | L44: =('ED Cal_Sample'!$J$11/'WB_LT Comm_Sample'!$E$14)*$E$7 -> 64.451613 | M44: =('ED Cal_Sample'!$K$11/'WB_LT Comm_Sample'!$E$14)*$E$8 -> 94.709677 | N44: =('ED Cal_Sample'!$L$11/'WB_LT Comm_Sample'!$E$14)*$E$9 -> 90.16129 | O44: =ROUNDUP(C44*$E$10,4) -> 1.5646 | P44: =ROUNDUP(C44*$E$11,4) -> 0.1613 | Q44: =H44*(100%+1%) -> 0 | R44: =$E$12/$E$14 -> 0.16129032 | S44: =ROUNDUP((S43-(K44+L44+M44+N44+O44+P44)),4)+Q44+R44 -> -3369.4376
C45: =$C$29/$E$14 -> 3.2258065 | F45: =F44+1 -> 45883 | G45: 7 | J45: =J44+1 -> 45883 | K45: =ROUND((($E$5*$E$17*G45)/$E$15),0)/$E$14 -> 6.7419355 | L45: =('ED Cal_Sample'!$J$11/'WB_LT Comm_Sample'!$E$14)*$E$7 -> 64.451613 | M45: =('ED Cal_Sample'!$K$11/'WB_LT Comm_Sample'!$E$14)*$E$8 -> 94.709677 | N45: =('ED Cal_Sample'!$L$11/'WB_LT Comm_Sample'!$E$14)*$E$9 -> 90.16129 | O45: =ROUNDUP(C45*$E$10,4) -> 1.5646 | P45: =ROUNDUP(C45*$E$11,4) -> 0.1613 | Q45: =H45*(100%+1%) -> 0 | R45: =$E$12/$E$14 -> 0.16129032 | S45: =ROUNDUP((S44-(K45+L45+M45+N45+O45+P45)),4)+Q45+R45 -> -3627.0668
C46: =$C$29/$E$14 -> 3.2258065 | F46: =F45+1 -> 45884 | G46: 7 | J46: =J45+1 -> 45884 | K46: =ROUND((($E$5*$E$17*G46)/$E$15),0)/$E$14 -> 6.7419355 | L46: =('ED Cal_Sample'!$J$11/'WB_LT Comm_Sample'!$E$14)*$E$7 -> 64.451613 | M46: =('ED Cal_Sample'!$K$11/'WB_LT Comm_Sample'!$E$14)*$E$8 -> 94.709677 | N46: =('ED Cal_Sample'!$L$11/'WB_LT Comm_Sample'!$E$14)*$E$9 -> 90.16129 | O46: =ROUNDUP(C46*$E$10,4) -> 1.5646 | P46: =ROUNDUP(C46*$E$11,4) -> 0.1613 | Q46: =H46*(100%+1%) -> 0 | R46: =$E$12/$E$14 -> 0.16129032 | S46: =ROUNDUP((S45-(K46+L46+M46+N46+O46+P46)),4)+Q46+R46 -> -3884.696
C47: =$C$29/$E$14 -> 3.2258065 | F47: =F46+1 -> 45885 | G47: 7 | J47: =J46+1 -> 45885 | K47: =ROUND((($E$5*$E$17*G47)/$E$15),0)/$E$14 -> 6.7419355 | L47: =('ED Cal_Sample'!$J$11/'WB_LT Comm_Sample'!$E$14)*$E$7 -> 64.451613 | M47: =('ED Cal_Sample'!$K$11/'WB_LT Comm_Sample'!$E$14)*$E$8 -> 94.709677 | N47: =('ED Cal_Sample'!$L$11/'WB_LT Comm_Sample'!$E$14)*$E$9 -> 90.16129 | O47: =ROUNDUP(C47*$E$10,4) -> 1.5646 | P47: =ROUNDUP(C47*$E$11,4) -> 0.1613 | Q47: =H47*(100%+1%) -> 0 | R47: =$E$12/$E$14 -> 0.16129032 | S47: =ROUNDUP((S46-(K47+L47+M47+N47+O47+P47)),4)+Q47+R47 -> -4142.3252
...

Sheet Addl MD Cal-Sample
F2: Sample Calculation
F3: Heads | G3: Value | H3: Details
F4: Addl Demand Charges | G4: 30 | H4: Rs /Per KVA
F5: Energy charges (TOU)
F6: Month | G6: 45870
F7: No. of Days | G7: =DAY(EOMONTH(G6,0)) -> 31
F8: No. of Hours | G8: =G7*24 -> 744
F9: ΣHi (Total restriction/load-shedding hours): | G9: 1.28
F10: Computed Demand Charge | G10: =$G$4 * (( $G$8 - $G$9 ) * MAX($I$22:$I$52)) / $G$8 -> 838.55484
F11: Multiplying Factor | G11: =$G$10 / (_xlfn.AGGREGATE(14,6,$I$22:$I$52,1) * $G$4) -> 0.99827957
F13: Variables | G13: KVA
F14: Contract Demand | G14: 10
E16: Off Peak | F16: Case 3a | G16: =G14+0.0001 -> 10.0001 | H16: =130%*G14 -> 13 | I16: 1.3
E17: Off Peak | F17: Case 3b | G17: =H16+0.0001 -> 13.0001 | H17: =150%*G14 -> 15 | I17: 1.5
E18: Off Peak | F18: Case 3c | G18: =H17+0.0001 -> 15.0001 | I18: >150% | K18: Maximum MD | L18: =MAX(I22:I52) -> 28
K19: Demand Charges | L19: =ROUND(('WB_LT Comm_Sample'!E5*'WB_LT Comm_Sample'!E17*'Addl MD Cal-Sample'!L18)/'WB_LT Comm_Sample'!E15,0) -> 837 | M19: This must be reconcilled on Fixed Charges
I20: Instantenous
B21: Date | C21: TOU1 Normal Time (Addl MD) | D21: TOU2 Peak Time (Addl MD) | E21: TOU3 Off-Peak Time (Addl MD) | G21: Slab TOU | H21: Case if (Off Peak Time) | I21: Addl MD Calculation (kVA) | K21: Test Result and Daily to match the overal Higest Value
B22: =G6 -> 45870 | G22: =IF(AND(C22>$G$14,C22=MAX(C22,D22,E22)),"Normal Time", IF(AND(D22>$G$14,D22=MAX(C22,D22,E22)),"Peak Time", IF(AND(E22>$G$14,E22=MAX(C22,D22,E22)),"Off-Peak Time",""))) | H22: =IF(G22="Off-Peak Time", IF(I22="","", IF(AND(I22>=$G$16,I22<=$H$16),$F$16, IF(AND(I22>=$G$17,I22<=$H$17),$F$17, IF(I22>=$G$18,$F$18,"")))), "") | I22: =IF(G22="Normal Time", IF(C22>$G$14, C22, ""), IF(G22="Peak Time", IF(D22>$G$14, D22, ""), IF(G22="Off-Peak Time", IF(E22>$G$14, E22, ""), ""))) | K22: Normal Time | M22: =IF(N22="","",0.2*(N22-G14)*G4) -> 108 | N22: {=IF($K$22<>"Normal Time","", _xlfn.LET(_xlpm.mx, IFERROR(_xlfn.AGGREGATE(14,6,$I$22:$I$52/($G$22:$G$52="Normal Time"),1),0), IF(_xlpm.mx<=0,"",_xlpm.mx) ) )} -> 28
B23: =B22+1 -> 45871 | G23: =IF(AND(C23>$G$14,C23=MAX(C23,D23,E23)),"Normal Time", IF(AND(D23>$G$14,D23=MAX(C23,D23,E23)),"Peak Time", IF(AND(E23>$G$14,E23=MAX(C23,D23,E23)),"Off-Peak Time",""))) | H23: =IF(G23="Off-Peak Time", IF(I23="","", IF(AND(I23>=$G$16,I23<=$H$16),$F$16, IF(AND(I23>=$G$17,I23<=$H$17),$F$17, IF(I23>=$G$18,$F$18,"")))), "") | I23: =IF(G23="Normal Time", IF(C23>$G$14, C23, ""), IF(G23="Peak Time", IF(D23>$G$14, D23, ""), IF(G23="Off-Peak Time", IF(E23>$G$14, E23, ""), ""))) | K23: Peak Time | M23: =IF(N23="","",0.5*(N23-G14)*G4) -> 60 | N23: {=IF($K$23<>"Peak Time","", _xlfn.LET(_xlpm.mx, IFERROR(_xlfn.AGGREGATE(14,6,$I$22:$I$52/($G$22:$G$52="Peak Time"),1),0), IF(_xlpm.mx<=0,"",_xlpm.mx) ) )} -> 14
B24: =B23+1 -> 45872 | G24: =IF(AND(C24>$G$14,C24=MAX(C24,D24,E24)),"Normal Time", IF(AND(D24>$G$14,D24=MAX(C24,D24,E24)),"Peak Time", IF(AND(E24>$G$14,E24=MAX(C24,D24,E24)),"Off-Peak Time",""))) | H24: =IF(G24="Off-Peak Time", IF(I24="","", IF(AND(I24>=$G$16,I24<=$H$16),$F$16, IF(AND(I24>=$G$17,I24<=$H$17),$F$17, IF(I24>=$G$18,$F$18,"")))), "") | I24: =IF(G24="Normal Time", IF(C24>$G$14, C24, ""), IF(G24="Peak Time", IF(D24>$G$14, D24, ""), IF(G24="Off-Peak Time", IF(E24>$G$14, E24, ""), ""))) | K24: Off-Peak Time | L24: =IF(OR($K$24<>"Off-Peak Time",COUNTIF($G$22:$G$52,"Off-Peak Time")=0),"", IF($N$24<=$G$14,"", IF($N$24<=1.3*$G$14,"Case 3a", IF($N$24<=1.5*$G$14,"Case 3b", IF($N$24>1.5*$G$14,"Case 3c","") ) ) ) ) -> Case 3c | M24: =IF(N24="","", IF(L24="Case 3a", 0.01*(N24-$G$14)*$G$4, IF(L24="Case 3b", (0.01*0.3*$G$14 + 0.1*(N24-1.3*$G$14))*$G$4, IF(L24="Case 3c", (0.01*0.3*$G$14 + 0.1*0.2*$G$14 + 0.2*(N24-1.5*$G$14))*$G$4, 0)))) -> 36.9 | N24: {=IF($K$24<>"Off-Peak Time","", _xlfn.LET(_xlpm.mx, IFERROR(_xlfn.AGGREGATE(14,6,$I$22:$I$52/($G$22:$G$52="Off-Peak Time"),1),0), IF(_xlpm.mx<=0,"",_xlpm.mx) ) )} -> 20
B25: =B24+1 -> 45873 | G25: =IF(AND(C25>$G$14,C25=MAX(C25,D25,E25)),"Normal Time", IF(AND(D25>$G$14,D25=MAX(C25,D25,E25)),"Peak Time", IF(AND(E25>$G$14,E25=MAX(C25,D25,E25)),"Off-Peak Time",""))) | H25: =IF(G25="Off-Peak Time", IF(I25="","", IF(AND(I25>=$G$16,I25<=$H$16),$F$16, IF(AND(I25>=$G$17,I25<=$H$17),$F$17, IF(I25>=$G$18,$F$18,"")))), "") | I25: =IF(G25="Normal Time", IF(C25>$G$14, C25, ""), IF(G25="Peak Time", IF(D25>$G$14, D25, ""), IF(G25="Off-Peak Time", IF(E25>$G$14, E25, ""), "")))
B26: =B25+1 -> 45874 | G26: =IF(AND(C26>$G$14,C26=MAX(C26,D26,E26)),"Normal Time", IF(AND(D26>$G$14,D26=MAX(C26,D26,E26)),"Peak Time", IF(AND(E26>$G$14,E26=MAX(C26,D26,E26)),"Off-Peak Time",""))) | H26: =IF(G26="Off-Peak Time", IF(I26="","", IF(AND(I26>=$G$16,I26<=$H$16),$F$16, IF(AND(I26>=$G$17,I26<=$H$17),$F$17, IF(I26>=$G$18,$F$18,"")))), "") | I26: =IF(G26="Normal Time", IF(C26>$G$14, C26, ""), IF(G26="Peak Time", IF(D26>$G$14, D26, ""), IF(G26="Off-Peak Time", IF(E26>$G$14, E26, ""), "")))
B27: =B26+1 -> 45875 | G27: =IF(AND(C27>$G$14,C27=MAX(C27,D27,E27)),"Normal Time", IF(AND(D27>$G$14,D27=MAX(C27,D27,E27)),"Peak Time", IF(AND(E27>$G$14,E27=MAX(C27,D27,E27)),"Off-Peak Time",""))) | H27: =IF(G27="Off-Peak Time", IF(I27="","", IF(AND(I27>=$G$16,I27<=$H$16),$F$16, IF(AND(I27>=$G$17,I27<=$H$17),$F$17, IF(I27>=$G$18,$F$18,"")))), "") | I27: =IF(G27="Normal Time", IF(C27>$G$14, C27, ""), IF(G27="Peak Time", IF(D27>$G$14, D27, ""), IF(G27="Off-Peak Time", IF(E27>$G$14, E27, ""), ""))) | L27: HIGHEST OF CASE 1, CASE 2 & CASE 3 | M27: =MAX(M22:M24) -> 108
B28: =B27+1 -> 45876 | G28: =IF(AND(C28>$G$14,C28=MAX(C28,D28,E28)),"Normal Time", IF(AND(D28>$G$14,D28=MAX(C28,D28,E28)),"Peak Time", IF(AND(E28>$G$14,E28=MAX(C28,D28,E28)),"Off-Peak Time",""))) | H28: =IF(G28="Off-Peak Time", IF(I28="","", IF(AND(I28>=$G$16,I28<=$H$16),$F$16, IF(AND(I28>=$G$17,I28<=$H$17),$F$17, IF(I28>=$G$18,$F$18,"")))), "") | I28: =IF(G28="Normal Time", IF(C28>$G$14, C28, ""), IF(G28="Peak Time", IF(D28>$G$14, D28, ""), IF(G28="Off-Peak Time", IF(E28>$G$14, E28, ""), ""))) | L28: Multiplying Factor | M28: =G11 -> 0.99827957
B29: =B28+1 -> 45877 | G29: =IF(AND(C29>$G$14,C29=MAX(C29,D29,E29)),"Normal Time", IF(AND(D29>$G$14,D29=MAX(C29,D29,E29)),"Peak Time", IF(AND(E29>$G$14,E29=MAX(C29,D29,E29)),"Off-Peak Time",""))) | H29: =IF(G29="Off-Peak Time", IF(I29="","", IF(AND(I29>=$G$16,I29<=$H$16),$F$16, IF(AND(I29>=$G$17,I29<=$H$17),$F$17, IF(I29>=$G$18,$F$18,"")))), "") | I29: =IF(G29="Normal Time", IF(C29>$G$14, C29, ""), IF(G29="Peak Time", IF(D29>$G$14, D29, ""), IF(G29="Off-Peak Time", IF(E29>$G$14, E29, ""), ""))) | L29: Net additional demand Charge | M29: =M27*M28 -> 107.81419
B30: =B29+1 -> 45878 | G30: =IF(AND(C30>$G$14,C30=MAX(C30,D30,E30)),"Normal Time", IF(AND(D30>$G$14,D30=MAX(C30,D30,E30)),"Peak Time", IF(AND(E30>$G$14,E30=MAX(C30,D30,E30)),"Off-Peak Time",""))) | H30: =IF(G30="Off-Peak Time", IF(I30="","", IF(AND(I30>=$G$16,I30<=$H$16),$F$16, IF(AND(I30>=$G$17,I30<=$H$17),$F$17, IF(I30>=$G$18,$F$18,"")))), "") | I30: =IF(G30="Normal Time", IF(C30>$G$14, C30, ""), IF(G30="Peak Time", IF(D30>$G$14, D30, ""), IF(G30="Off-Peak Time", IF(E30>$G$14, E30, ""), "")))
B31: =B30+1 -> 45879 | D31: 14 | G31: =IF(AND(C31>$G$14,C31=MAX(C31,D31,E31)),"Normal Time", IF(AND(D31>$G$14,D31=MAX(C31,D31,E31)),"Peak Time", IF(AND(E31>$G$14,E31=MAX(C31,D31,E31)),"Off-Peak Time",""))) -> Peak Time | H31: =IF(G31="Off-Peak Time", IF(I31="","", IF(AND(I31>=$G$16,I31<=$H$16),$F$16, IF(AND(I31>=$G$17,I31<=$H$17),$F$17, IF(I31>=$G$18,$F$18,"")))), "") | I31: =IF(G31="Normal Time", IF(C31>$G$14, C31, ""), IF(G31="Peak Time", IF(D31>$G$14, D31, ""), IF(G31="Off-Peak Time", IF(E31>$G$14, E31, ""), ""))) -> 14
B32: =B31+1 -> 45880 | G32: =IF(AND(C32>$G$14,C32=MAX(C32,D32,E32)),"Normal Time", IF(AND(D32>$G$14,D32=MAX(C32,D32,E32)),"Peak Time", IF(AND(E32>$G$14,E32=MAX(C32,D32,E32)),"Off-Peak Time",""))) | H32: =IF(G32="Off-Peak Time", IF(I32="","", IF(AND(I32>=$G$16,I32<=$H$16),$F$16, IF(AND(I32>=$G$17,I32<=$H$17),$F$17, IF(I32>=$G$18,$F$18,"")))), "") | I32: =IF(G32="Normal Time", IF(C32>$G$14, C32, ""), IF(G32="Peak Time", IF(D32>$G$14, D32, ""), IF(G32="Off-Peak Time", IF(E32>$G$14, E32, ""), "")))
B33: =B32+1 -> 45881 | E33: 20 | G33: =IF(AND(C33>$G$14,C33=MAX(C33,D33,E33)),"Normal Time", IF(AND(D33>$G$14,D33=MAX(C33,D33,E33)),"Peak Time", IF(AND(E33>$G$14,E33=MAX(C33,D33,E33)),"Off-Peak Time",""))) -> Off-Peak Time | H33: =IF(G33="Off-Peak Time", IF(I33="","", IF(AND(I33>=$G$16,I33<=$H$16),$F$16, IF(AND(I33>=$G$17,I33<=$H$17),$F$17, IF(I33>=$G$18,$F$18,"")))), "") -> Case 3c | I33: =IF(G33="Normal Time", IF(C33>$G$14, C33, ""), IF(G33="Peak Time", IF(D33>$G$14, D33, ""), IF(G33="Off-Peak Time", IF(E33>$G$14, E33, ""), ""))) -> 20
B34: =B33+1 -> 45882 | C34: 28 | G34: =IF(AND(C34>$G$14,C34=MAX(C34,D34,E34)),"Normal Time", IF(AND(D34>$G$14,D34=MAX(C34,D34,E34)),"Peak Time", IF(AND(E34>$G$14,E34=MAX(C34,D34,E34)),"Off-Peak Time",""))) -> Normal Time | H34: =IF(G34="Off-Peak Time", IF(I34="","", IF(AND(I34>=$G$16,I34<=$H$16),$F$16, IF(AND(I34>=$G$17,I34<=$H$17),$F$17, IF(I34>=$G$18,$F$18,"")))), "") | I34: =IF(G34="Normal Time", IF(C34>$G$14, C34, ""), IF(G34="Peak Time", IF(D34>$G$14, D34, ""), IF(G34="Off-Peak Time", IF(E34>$G$14, E34, ""), ""))) -> 28
B35: =B34+1 -> 45883 | G35: =IF(AND(C35>$G$14,C35=MAX(C35,D35,E35)),"Normal Time", IF(AND(D35>$G$14,D35=MAX(C35,D35,E35)),"Peak Time", IF(AND(E35>$G$14,E35=MAX(C35,D35,E35)),"Off-Peak Time",""))) | H35: =IF(G35="Off-Peak Time", IF(I35="","", IF(AND(I35>=$G$16,I35<=$H$16),$F$16, IF(AND(I35>=$G$17,I35<=$H$17),$F$17, IF(I35>=$G$18,$F$18,"")))), "") | I35: =IF(G35="Normal Time", IF(C35>$G$14, C35, ""), IF(G35="Peak Time", IF(D35>$G$14, D35, ""), IF(G35="Off-Peak Time", IF(E35>$G$14, E35, ""), "")))
B36: =B35+1 -> 45884 | G36: =IF(AND(C36>$G$14,C36=MAX(C36,D36,E36)),"Normal Time", IF(AND(D36>$G$14,D36=MAX(C36,D36,E36)),"Peak Time", IF(AND(E36>$G$14,E36=MAX(C36,D36,E36)),"Off-Peak Time",""))) | H36: =IF(G36="Off-Peak Time", IF(I36="","", IF(AND(I36>=$G$16,I36<=$H$16),$F$16, IF(AND(I36>=$G$17,I36<=$H$17),$F$17, IF(I36>=$G$18,$F$18,"")))), "") | I36: =IF(G36="Normal Time", IF(C36>$G$14, C36, ""), IF(G36="Peak Time", IF(D36>$G$14, D36, ""), IF(G36="Off-Peak Time", IF(E36>$G$14, E36, ""), "")))
B37: =B36+1 -> 45885 | G37: =IF(AND(C37>$G$14,C37=MAX(C37,D37,E37)),"Normal Time", IF(AND(D37>$G$14,D37=MAX(C37,D37,E37)),"Peak Time", IF(AND(E37>$G$14,E37=MAX(C37,D37,E37)),"Off-Peak Time",""))) | H37: =IF(G37="Off-Peak Time", IF(I37="","", IF(AND(I37>=$G$16,I37<=$H$16),$F$16, IF(AND(I37>=$G$17,I37<=$H$17),$F$17, IF(I37>=$G$18,$F$18,"")))), "") | I37: =IF(G37="Normal Time", IF(C37>$G$14, C37, ""), IF(G37="Peak Time", IF(D37>$G$14, D37, ""), IF(G37="Off-Peak Time", IF(E37>$G$14, E37, ""), "")))
B38: =B37+1 -> 45886 | G38: =IF(AND(C38>$G$14,C38=MAX(C38,D38,E38)),"Normal Time", IF(AND(D38>$G$14,D38=MAX(C38,D38,E38)),"Peak Time", IF(AND(E38>$G$14,E38=MAX(C38,D38,E38)),"Off-Peak Time",""))) | H38: =IF(G38="Off-Peak Time", IF(I38="","", IF(AND(I38>=$G$16,I38<=$H$16),$F$16, IF(AND(I38>=$G$17,I38<=$H$17),$F$17, IF(I38>=$G$18,$F$18,"")))), "") | I38: =IF(G38="Normal Time", IF(C38>$G$14, C38, ""), IF(G38="Peak Time", IF(D38>$G$14, D38, ""), IF(G38="Off-Peak Time", IF(E38>$G$14, E38, ""), "")))
B39: =B38+1 -> 45887 | G39: =IF(AND(C39>$G$14,C39=MAX(C39,D39,E39)),"Normal Time", IF(AND(D39>$G$14,D39=MAX(C39,D39,E39)),"Peak Time", IF(AND(E39>$G$14,E39=MAX(C39,D39,E39)),"Off-Peak Time",""))) | H39: =IF(G39="Off-Peak Time", IF(I39="","", IF(AND(I39>=$G$16,I39<=$H$16),$F$16, IF(AND(I39>=$G$17,I39<=$H$17),$F$17, IF(I39>=$G$18,$F$18,"")))), "") | I39: =IF(G39="Normal Time", IF(C39>$G$14, C39, ""), IF(G39="Peak Time", IF(D39>$G$14, D39, ""), IF(G39="Off-Peak Time", IF(E39>$G$14, E39, ""), "")))
B40: =B39+1 -> 45888 | G40: =IF(AND(C40>$G$14,C40=MAX(C40,D40,E40)),"Normal Time", IF(AND(D40>$G$14,D40=MAX(C40,D40,E40)),"Peak Time", IF(AND(E40>$G$14,E40=MAX(C40,D40,E40)),"Off-Peak Time",""))) | H40: =IF(G40="Off-Peak Time", IF(I40="","", IF(AND(I40>=$G$16,I40<=$H$16),$F$16, IF(AND(I40>=$G$17,I40<=$H$17),$F$17, IF(I40>=$G$18,$F$18,"")))), "") | I40: =IF(G40="Normal Time", IF(C40>$G$14, C40, ""), IF(G40="Peak Time", IF(D40>$G$14, D40, ""), IF(G40="Off-Peak Time", IF(E40>$G$14, E40, ""), "")))
B41: =B40+1 -> 45889 | G41: =IF(AND(C41>$G$14,C41=MAX(C41,D41,E41)),"Normal Time", IF(AND(D41>$G$14,D41=MAX(C41,D41,E41)),"Peak Time", IF(AND(E41>$G$14,E41=MAX(C41,D41,E41)),"Off-Peak Time",""))) | H41: =IF(G41="Off-Peak Time", IF(I41="","", IF(AND(I41>=$G$16,I41<=$H$16),$F$16, IF(AND(I41>=$G$17,I41<=$H$17),$F$17, IF(I41>=$G$18,$F$18,"")))), "") | I41: =IF(G41="Normal Time", IF(C41>$G$14, C41, ""), IF(G41="Peak Time", IF(D41>$G$14, D41, ""), IF(G41="Off-Peak Time", IF(E41>$G$14, E41, ""), "")))
B42: =B41+1 -> 45890 | G42: =IF(AND(C42>$G$14,C42=MAX(C42,D42,E42)),"Normal Time", IF(AND(D42>$G$14,D42=MAX(C42,D42,E42)),"Peak Time", IF(AND(E42>$G$14,E42=MAX(C42,D42,E42)),"Off-Peak Time",""))) | H42: =IF(G42="Off-Peak Time", IF(I42="","", IF(AND(I42>=$G$16,I42<=$H$16),$F$16, IF(AND(I42>=$G$17,I42<=$H$17),$F$17, IF(I42>=$G$18,$F$18,"")))), "") | I42: =IF(G42="Normal Time", IF(C42>$G$14, C42, ""), IF(G42="Peak Time", IF(D42>$G$14, D42, ""), IF(G42="Off-Peak Time", IF(E42>$G$14, E42, ""), "")))
B43: =B42+1 -> 45891 | G43: =IF(AND(C43>$G$14,C43=MAX(C43,D43,E43)),"Normal Time", IF(AND(D43>$G$14,D43=MAX(C43,D43,E43)),"Peak Time", IF(AND(E43>$G$14,E43=MAX(C43,D43,E43)),"Off-Peak Time",""))) | H43: =IF(G43="Off-Peak Time", IF(I43="","", IF(AND(I43>=$G$16,I43<=$H$16),$F$16, IF(AND(I43>=$G$17,I43<=$H$17),$F$17, IF(I43>=$G$18,$F$18,"")))), "") | I43: =IF(G43="Normal Time", IF(C43>$G$14, C43, ""), IF(G43="Peak Time", IF(D43>$G$14, D43, ""), IF(G43="Off-Peak Time", IF(E43>$G$14, E43, ""), "")))
...

Sheet ED Cal_Sample
G1: Month: | H1: 45870
J2: TOU1 | K2: TOU2 | L2: TOU3
J3: Normal Time | K3: Peak Time | L3: Off-Peak Time
J4: 0.25 | K4: 0.72916667 | L4: 0.97916667
J5: 0.70833333 | K5: 0.95833333 | L5: 0.22916667
I6: Month start date | J6: =EOMONTH(H1,-1)+1 -> 45870 | K6: =EOMONTH(H1,-1)+1 -> 45870 | L6: =EOMONTH(H1,-1)+1 -> 45870
I7: Month End date | J7: =EOMONTH(H1,0) -> 45900 | K7: =EOMONTH(H1,0) -> 45900 | L7: =EOMONTH(H1,0) -> 45900
I8: Intial Reading | J8: 100 | K8: 200 | L8: 100
I9: Final Reading | J9: 400 | K9: 600 | L9: 600
I11: Energy Consumption | J11: =J9-J8 -> 300 | K11: =K9-K8 -> 400 | L11: =L9-L8 -> 500 | N11: =SUM(J11:M11) -> 1200
I13: Energy Charges | J13: =J11*'WB_LT Comm_Sample'!E7 -> 1998 | K13: =K11*'WB_LT Comm_Sample'!E8 -> 2936 | L13: =L11*'WB_LT Comm_Sample'!E9 -> 2795 | N13: =SUM(J13:M13) -> 7729
I17: Energy Charges | J17: =N13 -> 7729
I18: Demand Charges | J18: ='Addl MD Cal-Sample'!L19 -> 837
I19: Addl MD | J19: ='Addl MD Cal-Sample'!M29 -> 107.81419
I20: Diff ECR | J20: ='WB_LT Comm_Sample'!O27 -> 48.5026
I21: MVCA | J21: ='WB_LT Comm_Sample'!P27 -> 5.0003
I23: Gross Amount | J23: =SUM(J17:J22) -> 8727.3171
C25: Energy Duty (ED)
C26: Slab Number | D26: Unit From | E26: Unit To | F26: %age | I26: ED Calculation
C27: 1 | D27: 0 | E27: 150 | F27: =$P$9 -> 0 | I27: Units | J27: =MIN(N11,150) -> 150 | K27: =ROUND($J$23*J27/$N$11*F27,0) -> 0
C28: 2 | D28: 151 | E28: 500 | F28: 0.1 | I28: Units | J28: =MIN(350,(N11-J27)) -> 350 | K28: =ROUND($J$23*J28/$N$11*F28,0) -> 255
C29: 3 | D29: 501 | E29: 1000 | F29: 0.125 | I29: Units | J29: =MIN(500,(N11-J27-J28)) -> 500 | K29: =ROUND($J$23*J29/$N$11*F29,0) -> 455
C30: 4 | D30: 1001 | E30: Max | F30: 0.15 | I30: Units | J30: =MAX(0,N11-J27-J28-J29) -> 200 | K30: =ROUND($J$23*J30/$N$11*F30,0) -> 218
J31: =SUM(J27:J30) -> 1200 | K31: =SUM(K27:K30) -> 928
